<?xml version="1.0"?>

<robot name="electric_jacker">
    <link name="base_footprint">
        <visual>
            <origin rpy="0 0 0" xyz="0 0 0"/>
            <geometry>
                <box size="0.001 0.001 0.001"/>
            </geometry>
        </visual>
    </link>
    <gazebo reference="base_footprint">
        <turnGravityOff>false</turnGravityOff>
    </gazebo>
    <joint name="base_footprint_joint" type="fixed">
        <origin rpy="0 0 0" xyz="0 0 0.04"/>
        <parent link="base_footprint"/>
        <child link="base_link"/>
    </joint>

	<!-- * * * Link Definitions * * * -->
    <link name="base_link">
        <visual>
            <origin rpy="0.0 0 0" xyz="0 0 0.025"/>
            <geometry>
                <mesh filename="package://electric_jacker_description/models/meshes/Base_Link.stl"/>
            </geometry>
        </visual>
         <inertial>
            <mass value="15"/>
            <origin xyz="0 0 0"/>
            <inertia ixx="0.16129" ixy="0" ixz="0" iyy="0.66854705" iyz="0" izz="0.66854705"/>
        </inertial>
        <collision>
            <origin rpy="0.0 0 0" xyz="0 0 0.025"/>
            <geometry>
                <mesh filename="package://electric_jacker_description/models/meshes/Base_Link.stl"/>
            </geometry>
        </collision>
        <gazebo reference="base_link">
            <material>Gazebo/Grey</material>
            <turnGravityOff>true</turnGravityOff>
        </gazebo>
	</link>

    <joint name="left_fork_joint" type="fixed">
        <parent link="base_link"/>
        <child link="left_fork_link"/>
        <origin xyz=".19 .12 0.025" rpy="0 0 0" />
    </joint>

    <link name="left_fork_link">
        <inertial>
            <mass value="10"/>
            <origin xyz="0 0 0"/>
            <inertia ixx="1.18978256667" ixy="0" ixz="0" iyy="0.0215053333333" iyz="0" izz="1.20698683333"/>
        </inertial>
        <visual>
            <origin rpy="0 0 0" xyz="0 0 0"/>
            <geometry>
                <mesh filename="package://electric_jacker_description/models/meshes/Fork_Link.stl"/>
            </geometry>
        </visual>
        <collision>
            <origin xyz="0 0 0"/>
            <geometry>
                <mesh filename="package://electric_jacker_description/models/meshes/Fork_Link.stl"/>
            </geometry>
        </collision>
        <gazebo reference="left_fork_link">
            <material>Gazebo/Grey</material>
            <turnGravityOff>false</turnGravityOff>
        </gazebo>
	</link>


    <joint name="right_fork_joint" type="fixed">
        <parent link="base_link"/>
        <child link="right_fork_link"/>
        <origin xyz="-.34 .12 0.025" rpy="0 0 0" />
    </joint>


    <link name="right_fork_link">
        <inertial>
            <mass value="10"/>
            <origin xyz="0 0 0"/>
            <inertia ixx="0.236558666667" ixy="0" ixz="0" iyy="0.980535673333" iyz="0" izz="0.980535673333"/>
        </inertial>
        <visual>
            <origin rpy="0.0 0 0" xyz="0 0 0"/>
            <geometry>
                <mesh filename="package://electric_jacker_description/models/meshes/Fork_Link.stl"/>
            </geometry>
        </visual>
        <collision>
            <origin xyz="0 0 0"/>
            <geometry>
                <mesh filename="package://electric_jacker_description/models/meshes/Fork_Link.stl"/>
            </geometry>
        </collision>
        <gazebo reference="right_fork_link">
            <material>Gazebo/Grey</material>
            <turnGravityOff>false</turnGravityOff>
        </gazebo>
	</link>

    <link name="right_wheel_link">
        <visual>
            <origin rpy="1.57079632679 0  -1.57079632679 " xyz="0 0 0"/>
            <geometry>
                <cylinder length="0.0508" radius="0.0889"/>
            </geometry>
        </visual>
        <collision>
            <origin rpy="1.57079632679 0  -1.57079632679 " xyz="0 0 0"/>
            <geometry>
                <cylinder length="0.0508" radius="0.0889"/>
            </geometry>
        </collision>
        <inertial>
            <mass value="2.5"/>
            <origin xyz="0 0 0"/>
            <inertia ixx="0.00547713958333" ixy="0" ixz="0" iyy="0.00547713958333" iyz="0" izz="0.0098790125"/>
        </inertial>
        <gazebo reference="right_wheel_link">
            <mu1 value="1.0"/>
            <mu2 value="1.0"/>
            <kp value="10000.0"/>
            <kd value="1000.0"/>
            <material>Gazebo/Blue</material>
            <turnGravityOff>false</turnGravityOff>
        </gazebo>
  </link>

   <joint name="right_wheel_joint" type="continuous">
        <parent link="base_link"/>
        <child link="right_wheel_link"/>
        <parent link="base_link"/>
        <child link="right_wheel_link"/>
        <origin rpy="0 0 0" xyz="0.27 0 0.09"/>
        <axis rpy="0  0" xyz="1 0 0"/>
        <limit effort="100" velocity="100"/>
        <joint_properties damping="0.0" friction="0.0"/>
  </joint>
  <!-- Transmission is important to link the joints and the controller -->
    <!-- <transmission name="right_wheel_joint_trans">
        <type>transmission_interface/SimpleTransmission</type>
        <joint name="right_wheel_joint"/>
        <actuator name="right_wheel_joint_motor">
            <hardwareInterface>EffortJointInterface</hardwareInterface>
            <mechanicalReduction>1</mechanicalReduction>
        </actuator>
  </transmission> -->

    <link name="left_wheel_link">
        <visual>
            <origin rpy="-1.57079632679 0  1.57079632679 " xyz="0 0 0"/>
            <geometry>
                <cylinder length="0.0508" radius="0.0889"/>
            </geometry>
        </visual>
        <collision>
            <origin rpy="-1.57079632679 0  1.57079632679 " xyz="0 0 0"/>
            <geometry>
                <cylinder length="0.0508" radius="0.0889"/>
            </geometry>
        </collision>
        <inertial>
            <mass value="2.5"/>
            <origin xyz="0 0 0"/>
            <inertia ixx="0.00547713958333" ixy="0" ixz="0" iyy="0.00547713958333" iyz="0" izz="0.0098790125"/>
        </inertial>
        <gazebo reference="left_wheel_link">
            <mu1 value="1.0"/>
            <mu2 value="1.0"/>
            <kp value="10000.0"/>
            <kd value="1000.0"/>
            <material>Gazebo/Red</material>
            <turnGravityOff>false</turnGravityOff>
        </gazebo>
  </link>

   <joint name="left_wheel_joint" type="continuous">
        <parent link="base_link"/>
        <child link="left_wheel_link"/>
        <parent link="base_link"/>
        <child link="left_wheel_link"/>
        <origin rpy="0 0 0" xyz="-0.27 0 0.09"/>
        <axis rpy="0  0" xyz="1 0 0"/>
        <limit effort="100" velocity="100"/>
        <joint_properties damping="0.0" friction="0.0"/>
  </joint>
  <!-- Transmission is important to link the joints and the controller -->
    <!-- <transmission name="left_wheel_joint_trans">
        <type>transmission_interface/SimpleTransmission</type>
        <joint name="left_wheel_joint"/>
        <actuator name="left_wheel_joint_motor">
            <hardwareInterface>EffortJointInterface</hardwareInterface>
            <mechanicalReduction>1</mechanicalReduction>
        </actuator>
  </transmission> -->


    <link name="right_fork_caster_link">
        <visual>
            <origin rpy="1.57079632679 0 0" xyz="0 0 0"/>
            <geometry>
                <sphere radius="0.025"/>
            </geometry>
        </visual>
        <collision>
            <origin rpy="1.57079632679 0 0" xyz="0 0 0"/>
            <geometry>
                <sphere radius="0.025"/>
            </geometry>
        </collision>
        <inertial>
            <mass value="0.5"/>
            <origin xyz="0 0 0"/>
            <inertia ixx="0.000125" ixy="0.0" ixz="0.0" iyy="0.000125" iyz="0.0" izz="0.000125"/>
        </inertial>
        <gazebo reference="right_fork_caster_link">
            <turnGravityOff>false</turnGravityOff>
        </gazebo>
    </link>

    <joint name="right_fork_caster_joint" type="fixed">
        <parent link="right_fork_link"/>
        <child link="right_fork_caster_link"/>
        <origin rpy="-1.57079632679 0 0" xyz="0.0762 1 0"/>
    </joint>


    <link name="left_fork_caster_link">
        <visual>
            <origin rpy="1.57079632679 0 0" xyz="0 0 0"/>
            <geometry>
                <sphere radius="0.025"/>
            </geometry>
        </visual>
        <collision>
            <origin rpy="1.57079632679 0 0" xyz="0 0 0"/>
            <geometry>
                <sphere radius="0.025"/>
            </geometry>
        </collision>
        <inertial>
            <mass value="0.5"/>
            <origin xyz="0 0 0"/>
            <inertia ixx="0.000125" ixy="0.0" ixz="0.0" iyy="0.000125" iyz="0.0" izz="0.000125"/>
        </inertial>
        <gazebo reference="left_fork_caster_link">
            <turnGravityOff>false</turnGravityOff>
        </gazebo>
    </link>

    <joint name="left_fork_caster_joint" type="fixed">
        <parent link="left_fork_link"/>
        <child link="left_fork_caster_link"/>
        <origin rpy="-1.57079632679 0 0" xyz="0.0762 1 0"/>
    </joint>


    <gazebo>
        <static>False</static>
    </gazebo>

    <gazebo>
        <plugin name="differential_drive_controller" filename="libgazebo_ros_diff_drive.so">

            <!-- Plugin update rate in Hz -->
            <updateRate>5</updateRate>

            <!-- Name of left joint, defaults to `left_joint` -->
            <leftJoint>left_wheel_joint</leftJoint>

            <!-- Name of right joint, defaults to `right_joint` -->
            <rightJoint>right_wheel_joint</rightJoint>

            <!-- The distance from the center of one wheel to the other, in meters, defaults to 0.34 m -->
            <wheelSeparation>0.53848</wheelSeparation>

            <!-- Diameter of the wheels, in meters, defaults to 0.15 m -->
            <wheelDiameter>0.1778</wheelDiameter>

            <!-- Wheel acceleration, in rad/s^2, defaults to 0.0 rad/s^2 -->
            <wheelAcceleration>0.0</wheelAcceleration>

            <!-- Maximum torque which the wheels can produce, in Nm, defaults to 5 Nm -->
            <wheelTorque>90</wheelTorque>

            <!-- Topic to receive geometry_msgs/Twist message commands, defaults to `cmd_vel` -->
            <commandTopic>cmd_vel</commandTopic>

            <!-- Topic to publish nav_msgs/Odometry messages, defaults to `odom` -->
            <odometryTopic>odom</odometryTopic>

            <!-- Odometry frame, defaults to `odom` -->
            <odometryFrame>odom</odometryFrame>

            <!-- Robot frame to calculate odometry from, defaults to `base_footprint` -->
            <robotBaseFrame>base_footprint</robotBaseFrame>

            <!-- Odometry source, 0 for ENCODER, 1 for WORLD, defaults to WORLD -->
            <odometrySource>1</odometrySource>

            <!-- Set to true to publish transforms for the wheel links, defaults to false -->
            <publishWheelTF>true</publishWheelTF>

            <!-- Set to true to publish transforms for the odometry, defaults to true -->
            <publishOdom>true</publishOdom>

            <!-- Set to true to publish sensor_msgs/JointState on /joint_states for the wheel joints, defaults to false -->
            <publishWheelJointState>true</publishWheelJointState>

            <!-- Set to true to swap right and left wheels, defaults to true -->
            <legacyMode>false</legacyMode>
        </plugin>
    </gazebo>


    <gazebo reference="camera_depth_frame">
        <sensor name="kinect" type="depth">
            <always_on>true</always_on>
            <update_rate>20.0</update_rate>
            <camera>
                <horizontal_fov>1.0471975512</horizontal_fov>
                <image>
                    <format>R8G8B8</format>
                    <width>640</width>
                    <height>480</height>
                </image>
                <clip>
                    <near>0.05</near>
                    <far>8.0</far>
                </clip>
            </camera>
            <plugin filename="libgazebo_ros_openni_kinect.so" name="camera_depth_frame_kinect_controller">
                <baseline>0.1</baseline>
                <alwaysOn>true</alwaysOn>
                <updateRate>10</updateRate>
                <cameraName>camera1</cameraName>
                <imageTopicName>depth/image_raw</imageTopicName>
                <cameraInfoTopicName>depth/camera_info</cameraInfoTopicName>
                <depthImageTopicName>depth/image_raw</depthImageTopicName>
                <depthImageCameraInfoTopicName>depth/camera_info</depthImageCameraInfoTopicName>
                <pointCloudTopicName>depth/points</pointCloudTopicName>
                <frameName>camera_depth_optical_frame</frameName>
                <pointCloudCutoff>0.3</pointCloudCutoff>
                <distortion_k1>0.0</distortion_k1>
                <distortion_k2>0.0</distortion_k2>
                <distortion_k3>0.0</distortion_k3>
                <distortion_t1>0.0</distortion_t1>
                <distortion_t2>0.0</distortion_t2>
                <!--
                <CxPrime>0</CxPrime>
                <Cx>0</Cx>
                <Cy>0</Cy>
                <focalLength>0</focalLength>
                <hackBaseline>0</hackBaseline>
                -->
            </plugin>
        </sensor>
    </gazebo>

    <!-- Parameterised in part by the values in kinect_properties.urdf.xacro -->
    <joint name="camera_rgb_joint" type="fixed">
        <origin rpy="0 0 0" xyz="0.0 -0.127 0.1778"/>
        <parent link="base_link"/>
        <child link="camera_rgb_frame"/>
    </joint>
    <link name="camera_rgb_frame">
        <inertial>
            <mass value="0.001"/>
            <origin xyz="0 0 0"/>
            <inertia ixx="0.0001" ixy="0.0" ixz="0.0" iyy="0.0001" iyz="0.0" izz="0.0001"/>
        </inertial>
    </link>
    <joint name="camera_rgb_optical_joint" type="fixed">
        <origin rpy="-1.57079632679 0 -1.57079632679" xyz="0 0 0"/>
        <parent link="camera_rgb_frame"/>
        <child link="camera_rgb_optical_frame"/>
    </joint>
    <link name="camera_rgb_optical_frame">
        <inertial>
            <mass value="0.001"/>
            <origin xyz="0 0 0"/>
            <inertia ixx="0.0001" ixy="0.0" ixz="0.0" iyy="0.0001" iyz="0.0" izz="0.0001"/>
        </inertial>
    </link>
    <joint name="camera_joint" type="fixed">
        <origin rpy="0 0 0" xyz="-0.031 -0.0 -0.016"/>
        <parent link="camera_rgb_frame"/>
        <child link="camera_link"/>
    </joint>
    <link name="camera_link">
        <visual>
            <origin rpy="0 0 0" xyz="0 0 0"/>
            <geometry>
                <mesh filename="package://electric_jacker_description/models/meshes/kinect.dae"/>
            </geometry>
        </visual>
            <collision>
            <origin rpy="0 0 0" xyz="0.0 -0.127 0.1778"/>
            <geometry>
                <box size="0.07271 0.27794 0.073"/>
            </geometry>
        </collision>
        <inertial>
            <mass value="0.001"/>
            <origin xyz="0 0 0"/>
            <inertia ixx="0.0001" ixy="0.0" ixz="0.0" iyy="0.0001" iyz="0.0" izz="0.0001"/>
        </inertial>
    </link>
    <!-- The fixed joints & links below are usually published by static_transformers launched by the OpenNi launch 
        files. However, for Gazebo simulation we need them, so we add them here.
        (Hence, don't publish them additionally!) -->
    <joint name="camera_depth_joint" type="fixed">
        <origin rpy="0 0 0" xyz="0 0.0 0"/>
        <parent link="camera_rgb_frame"/>
        <child link="camera_depth_frame"/>
    </joint>
    <link name="camera_depth_frame">
        <inertial>
            <mass value="0.001"/>
            <origin xyz="0 0 0"/>
            <inertia ixx="0.0001" ixy="0.0" ixz="0.0" iyy="0.0001" iyz="0.0" izz="0.0001"/>
        </inertial>
    </link>
        <joint name="camera_depth_optical_joint" type="fixed">
        <origin rpy="-1.57079632679 0 -1.57079632679" xyz="0 0 0"/>
        <parent link="camera_depth_frame"/>
        <child link="camera_depth_optical_frame"/>
    </joint>
    <link name="camera_depth_optical_frame">
        <inertial>
            <mass value="0.001"/>
            <origin xyz="0 0 0"/>
            <inertia ixx="0.0001" ixy="0.0" ixz="0.0" iyy="0.0001" iyz="0.0" izz="0.0001"/>
        </inertial>
    </link>


</robot>